 2019-04-16 18:31:57 views.py[line:241] ERROR '趋势图数据'
 2019-04-16 18:31:57 views.py[line:241] ERROR '计划'
 2019-04-16 18:47:02 views.py[line:245] ERROR 'str' object cannot be interpreted as an integer
 2019-04-16 18:47:02 views.py[line:245] ERROR Invalid field name(s) for model BxEverydayData: 'end_time', 'pic_count', 'pic_time_gap', 'start_time', 'station_name', 'status'.
 2019-04-16 18:49:07 views.py[line:246] ERROR 'str' object cannot be interpreted as an integer
 2019-04-16 18:49:07 views.py[line:246] ERROR Invalid field name(s) for model BxText: 'end_time', 'pic_count', 'pic_time_gap', 'start_time', 'station_id', 'station_name', 'status'.
 2019-04-16 18:50:08 views.py[line:246] ERROR 'str' object cannot be interpreted as an integer
 2019-04-16 18:50:09 views.py[line:246] ERROR 'str' object cannot be interpreted as an integer
 2019-04-16 18:51:30 views.py[line:246] ERROR Invalid field name(s) for model BxText: 'end_time', 'pic_count', 'pic_time_gap', 'start_time', 'station_id', 'station_name', 'status'.
 2019-04-16 18:52:39 views.py[line:247] ERROR 'str' object cannot be interpreted as an integer
 2019-04-16 18:52:40 views.py[line:247] ERROR 'str' object cannot be interpreted as an integer
 2019-04-16 18:55:45 views.py[line:247] ERROR 'str' object cannot be interpreted as an integer
 2019-04-16 18:55:46 views.py[line:247] ERROR 'str' object cannot be interpreted as an integer
 2019-04-16 18:56:21 views.py[line:247] ERROR 'str' object cannot be interpreted as an integer
 2019-04-16 18:56:21 views.py[line:247] ERROR 'str' object cannot be interpreted as an integer
 2019-04-16 18:56:59 views.py[line:247] ERROR 'str' object cannot be interpreted as an integer
 2019-04-16 18:56:59 views.py[line:247] ERROR 'str' object cannot be interpreted as an integer
 2019-04-16 18:57:00 views.py[line:247] ERROR 'str' object cannot be interpreted as an integer
 2019-04-16 18:59:52 views.py[line:247] ERROR '趋势图数据'
 2019-04-16 18:59:52 views.py[line:247] ERROR 'str' object cannot be interpreted as an integer
 2019-04-16 18:59:52 views.py[line:247] ERROR 'str' object cannot be interpreted as an integer
 2019-04-16 18:59:52 views.py[line:247] ERROR 'str' object cannot be interpreted as an integer
 2019-04-16 18:59:52 views.py[line:247] ERROR '计划'
 2019-04-16 18:59:52 views.py[line:247] ERROR 'str' object cannot be interpreted as an integer
 2019-04-16 18:59:53 views.py[line:247] ERROR 'str' object cannot be interpreted as an integer
 2019-04-16 19:04:39 views.py[line:248] ERROR 'str' object cannot be interpreted as an integer
 2019-04-16 19:04:39 views.py[line:248] ERROR 'str' object cannot be interpreted as an integer
 2019-04-16 19:07:28 views.py[line:248] ERROR 'str' object cannot be interpreted as an integer
 2019-04-18 16:34:37 exception.py[line:135] ERROR Internal Server Error: /export_excel
Traceback (most recent call last):
  File "E:\BrandMax\lib\site-packages\django\core\handlers\exception.py", line 41, in inner
    response = get_response(request)
  File "E:\BrandMax\lib\site-packages\django\core\handlers\base.py", line 198, in _get_response
    "returned None instead." % (callback.__module__, view_name)
ValueError: The view excel_import.views.Excel_export didn't return an HttpResponse object. It returned None instead.
 2019-04-18 16:37:39 csrf.py[line:160] WARNING Forbidden (CSRF token missing or incorrect.): /export_excel
 2019-04-18 16:38:03 exception.py[line:135] ERROR Internal Server Error: /export_excel
Traceback (most recent call last):
  File "E:\BrandMax\lib\site-packages\django\core\handlers\exception.py", line 41, in inner
    response = get_response(request)
  File "E:\BrandMax\lib\site-packages\django\core\handlers\base.py", line 187, in _get_response
    response = self.process_exception_by_middleware(e, request)
  File "E:\BrandMax\lib\site-packages\django\core\handlers\base.py", line 185, in _get_response
    response = wrapped_callback(request, *callback_args, **callback_kwargs)
  File "E:\BrandMax\lib\site-packages\django\views\generic\base.py", line 68, in view
    return self.dispatch(request, *args, **kwargs)
  File "E:\BrandMax\lib\site-packages\django\views\generic\base.py", line 88, in dispatch
    return handler(request, *args, **kwargs)
  File "E:\BrandMax\ExcelImport\excel_import\views.py", line 272, in post
    sheet = workbook.add_sheet(sheet_name, cell_overwrite_ok=True)
  File "E:\BrandMax\lib\site-packages\xlwt\Workbook.py", line 366, in add_sheet
    sheetname = sheetname.decode(self.encoding)
AttributeError: 'NoneType' object has no attribute 'decode'
 2019-04-18 16:38:40 exception.py[line:135] ERROR Internal Server Error: /export_excel
Traceback (most recent call last):
  File "E:\BrandMax\lib\site-packages\django\core\handlers\exception.py", line 41, in inner
    response = get_response(request)
  File "E:\BrandMax\lib\site-packages\django\core\handlers\base.py", line 187, in _get_response
    response = self.process_exception_by_middleware(e, request)
  File "E:\BrandMax\lib\site-packages\django\core\handlers\base.py", line 185, in _get_response
    response = wrapped_callback(request, *callback_args, **callback_kwargs)
  File "E:\BrandMax\lib\site-packages\django\views\generic\base.py", line 68, in view
    return self.dispatch(request, *args, **kwargs)
  File "E:\BrandMax\lib\site-packages\django\views\generic\base.py", line 88, in dispatch
    return handler(request, *args, **kwargs)
  File "E:\BrandMax\ExcelImport\excel_import\views.py", line 273, in post
    sheet = workbook.add_sheet(sheet_name, cell_overwrite_ok=True)
  File "E:\BrandMax\lib\site-packages\xlwt\Workbook.py", line 366, in add_sheet
    sheetname = sheetname.decode(self.encoding)
AttributeError: 'NoneType' object has no attribute 'decode'
 2019-04-18 16:46:16 exception.py[line:135] ERROR Internal Server Error: /export/
Traceback (most recent call last):
  File "E:\BrandMax\lib\site-packages\django\core\handlers\exception.py", line 41, in inner
    response = get_response(request)
  File "E:\BrandMax\lib\site-packages\django\core\handlers\base.py", line 187, in _get_response
    response = self.process_exception_by_middleware(e, request)
  File "E:\BrandMax\lib\site-packages\django\core\handlers\base.py", line 185, in _get_response
    response = wrapped_callback(request, *callback_args, **callback_kwargs)
TypeError: export() missing 1 required positional argument: 'request'
 2019-04-18 16:49:09 exception.py[line:135] ERROR Internal Server Error: /export/
Traceback (most recent call last):
  File "E:\BrandMax\lib\site-packages\django\core\handlers\exception.py", line 41, in inner
    response = get_response(request)
  File "E:\BrandMax\lib\site-packages\django\core\handlers\base.py", line 187, in _get_response
    response = self.process_exception_by_middleware(e, request)
  File "E:\BrandMax\lib\site-packages\django\core\handlers\base.py", line 185, in _get_response
    response = wrapped_callback(request, *callback_args, **callback_kwargs)
  File "E:\BrandMax\lib\site-packages\django\views\generic\base.py", line 68, in view
    return self.dispatch(request, *args, **kwargs)
  File "E:\BrandMax\lib\site-packages\django\views\generic\base.py", line 88, in dispatch
    return handler(request, *args, **kwargs)
  File "E:\BrandMax\ExcelImport\excel_import\views.py", line 274, in get
    sheet_name = request.Get.get('sheet_name')
AttributeError: 'WSGIRequest' object has no attribute 'Get'
 2019-04-18 16:50:02 exception.py[line:135] ERROR Internal Server Error: /export/
Traceback (most recent call last):
  File "E:\BrandMax\lib\site-packages\django\core\handlers\exception.py", line 41, in inner
    response = get_response(request)
  File "E:\BrandMax\lib\site-packages\django\core\handlers\base.py", line 187, in _get_response
    response = self.process_exception_by_middleware(e, request)
  File "E:\BrandMax\lib\site-packages\django\core\handlers\base.py", line 185, in _get_response
    response = wrapped_callback(request, *callback_args, **callback_kwargs)
  File "E:\BrandMax\lib\site-packages\django\views\generic\base.py", line 68, in view
    return self.dispatch(request, *args, **kwargs)
  File "E:\BrandMax\lib\site-packages\django\views\generic\base.py", line 88, in dispatch
    return handler(request, *args, **kwargs)
  File "E:\BrandMax\ExcelImport\excel_import\views.py", line 274, in get
    print(request.Get)
AttributeError: 'WSGIRequest' object has no attribute 'Get'
 2019-04-18 16:50:22 exception.py[line:135] ERROR Internal Server Error: /export/
Traceback (most recent call last):
  File "E:\BrandMax\lib\site-packages\django\core\handlers\exception.py", line 41, in inner
    response = get_response(request)
  File "E:\BrandMax\lib\site-packages\django\core\handlers\base.py", line 187, in _get_response
    response = self.process_exception_by_middleware(e, request)
  File "E:\BrandMax\lib\site-packages\django\core\handlers\base.py", line 185, in _get_response
    response = wrapped_callback(request, *callback_args, **callback_kwargs)
  File "E:\BrandMax\lib\site-packages\django\views\generic\base.py", line 68, in view
    return self.dispatch(request, *args, **kwargs)
  File "E:\BrandMax\lib\site-packages\django\views\generic\base.py", line 88, in dispatch
    return handler(request, *args, **kwargs)
  File "E:\BrandMax\ExcelImport\excel_import\views.py", line 275, in get
    sheet_name = request.Get.get('sheet_name')
AttributeError: 'WSGIRequest' object has no attribute 'Get'
 2019-04-18 16:51:08 exception.py[line:135] ERROR Internal Server Error: /export/
Traceback (most recent call last):
  File "E:\BrandMax\lib\site-packages\django\core\handlers\exception.py", line 41, in inner
    response = get_response(request)
  File "E:\BrandMax\lib\site-packages\django\core\handlers\base.py", line 187, in _get_response
    response = self.process_exception_by_middleware(e, request)
  File "E:\BrandMax\lib\site-packages\django\core\handlers\base.py", line 185, in _get_response
    response = wrapped_callback(request, *callback_args, **callback_kwargs)
  File "E:\BrandMax\lib\site-packages\django\views\generic\base.py", line 68, in view
    return self.dispatch(request, *args, **kwargs)
  File "E:\BrandMax\lib\site-packages\django\views\generic\base.py", line 88, in dispatch
    return handler(request, *args, **kwargs)
  File "E:\BrandMax\ExcelImport\excel_import\views.py", line 279, in get
    model = getattr(models, sheet_name)
AttributeError: module 'excel_import.models' has no attribute '文本'
 2019-04-18 16:53:44 exception.py[line:135] ERROR Internal Server Error: /export/
Traceback (most recent call last):
  File "E:\BrandMax\lib\site-packages\django\core\handlers\exception.py", line 41, in inner
    response = get_response(request)
  File "E:\BrandMax\lib\site-packages\django\core\handlers\base.py", line 187, in _get_response
    response = self.process_exception_by_middleware(e, request)
  File "E:\BrandMax\lib\site-packages\django\core\handlers\base.py", line 185, in _get_response
    response = wrapped_callback(request, *callback_args, **callback_kwargs)
  File "E:\BrandMax\lib\site-packages\django\views\generic\base.py", line 68, in view
    return self.dispatch(request, *args, **kwargs)
  File "E:\BrandMax\lib\site-packages\django\views\generic\base.py", line 88, in dispatch
    return handler(request, *args, **kwargs)
  File "E:\BrandMax\ExcelImport\excel_import\views.py", line 306, in get
    return redirect('ex')
  File "E:\BrandMax\lib\site-packages\django\shortcuts.py", line 56, in redirect
    return redirect_class(resolve_url(to, *args, **kwargs))
  File "E:\BrandMax\lib\site-packages\django\shortcuts.py", line 147, in resolve_url
    return reverse(to, args=args, kwargs=kwargs)
  File "E:\BrandMax\lib\site-packages\django\urls\base.py", line 91, in reverse
    return force_text(iri_to_uri(resolver._reverse_with_prefix(view, prefix, *args, **kwargs)))
  File "E:\BrandMax\lib\site-packages\django\urls\resolvers.py", line 497, in _reverse_with_prefix
    raise NoReverseMatch(msg)
django.urls.exceptions.NoReverseMatch: Reverse for 'ex' not found. 'ex' is not a valid view function or pattern name.
 2019-04-18 16:57:02 exception.py[line:135] ERROR Internal Server Error: /export/
Traceback (most recent call last):
  File "E:\BrandMax\lib\site-packages\django\core\handlers\exception.py", line 41, in inner
    response = get_response(request)
  File "E:\BrandMax\lib\site-packages\django\core\handlers\base.py", line 187, in _get_response
    response = self.process_exception_by_middleware(e, request)
  File "E:\BrandMax\lib\site-packages\django\core\handlers\base.py", line 185, in _get_response
    response = wrapped_callback(request, *callback_args, **callback_kwargs)
  File "E:\BrandMax\lib\site-packages\django\views\generic\base.py", line 68, in view
    return self.dispatch(request, *args, **kwargs)
  File "E:\BrandMax\lib\site-packages\django\views\generic\base.py", line 88, in dispatch
    return handler(request, *args, **kwargs)
  File "E:\BrandMax\ExcelImport\excel_import\views.py", line 306, in get
    return redirect('ex')
  File "E:\BrandMax\lib\site-packages\django\shortcuts.py", line 56, in redirect
    return redirect_class(resolve_url(to, *args, **kwargs))
  File "E:\BrandMax\lib\site-packages\django\shortcuts.py", line 147, in resolve_url
    return reverse(to, args=args, kwargs=kwargs)
  File "E:\BrandMax\lib\site-packages\django\urls\base.py", line 91, in reverse
    return force_text(iri_to_uri(resolver._reverse_with_prefix(view, prefix, *args, **kwargs)))
  File "E:\BrandMax\lib\site-packages\django\urls\resolvers.py", line 497, in _reverse_with_prefix
    raise NoReverseMatch(msg)
django.urls.exceptions.NoReverseMatch: Reverse for 'ex' not found. 'ex' is not a valid view function or pattern name.
 2019-04-18 17:43:10 exception.py[line:135] ERROR Internal Server Error: /index
Traceback (most recent call last):
  File "E:\BrandMax\lib\site-packages\django\core\handlers\exception.py", line 41, in inner
    response = get_response(request)
  File "E:\BrandMax\lib\site-packages\django\core\handlers\base.py", line 187, in _get_response
    response = self.process_exception_by_middleware(e, request)
  File "E:\BrandMax\lib\site-packages\django\core\handlers\base.py", line 185, in _get_response
    response = wrapped_callback(request, *callback_args, **callback_kwargs)
  File "E:\BrandMax\lib\site-packages\django\views\generic\base.py", line 68, in view
    return self.dispatch(request, *args, **kwargs)
  File "E:\BrandMax\lib\site-packages\django\views\generic\base.py", line 88, in dispatch
    return handler(request, *args, **kwargs)
  File "E:\BrandMax\ExcelImport\excel_import\views.py", line 307, in get
    return render('base.html')
TypeError: render() missing 1 required positional argument: 'template_name'
 2019-04-18 17:59:25 exception.py[line:135] ERROR Internal Server Error: /index
Traceback (most recent call last):
  File "E:\BrandMax\lib\site-packages\django\template\backends\django.py", line 66, in render
    return self.template.render(context)
  File "E:\BrandMax\lib\site-packages\django\template\base.py", line 207, in render
    return self._render(context)
  File "E:\BrandMax\lib\site-packages\django\template\base.py", line 199, in _render
    return self.nodelist.render(context)
  File "E:\BrandMax\lib\site-packages\django\template\base.py", line 990, in render
    bit = node.render_annotated(context)
  File "E:\BrandMax\lib\site-packages\django\template\base.py", line 957, in render_annotated
    return self.render(context)
  File "E:\BrandMax\lib\site-packages\django\template\loader_tags.py", line 216, in render
    return template.render(context)
  File "E:\BrandMax\lib\site-packages\django\template\base.py", line 209, in render
    return self._render(context)
  File "E:\BrandMax\lib\site-packages\django\template\base.py", line 199, in _render
    return self.nodelist.render(context)
  File "E:\BrandMax\lib\site-packages\django\template\base.py", line 990, in render
    bit = node.render_annotated(context)
  File "E:\BrandMax\lib\site-packages\django\template\base.py", line 957, in render_annotated
    return self.render(context)
  File "E:\BrandMax\lib\site-packages\django\template\loader_tags.py", line 154, in render
    compiled_parent = self.get_parent(context)
  File "E:\BrandMax\lib\site-packages\django\template\loader_tags.py", line 151, in get_parent
    return self.find_template(parent, context)
  File "E:\BrandMax\lib\site-packages\django\template\loader_tags.py", line 131, in find_template
    template_name, skip=history,
  File "E:\BrandMax\lib\site-packages\django\template\engine.py", line 148, in find_template
    raise TemplateDoesNotExist(name, tried=tried)
django.template.exceptions.TemplateDoesNotExist: base.html

During handling of the above exception, another exception occurred:

Traceback (most recent call last):
  File "E:\BrandMax\lib\site-packages\django\core\handlers\exception.py", line 41, in inner
    response = get_response(request)
  File "E:\BrandMax\lib\site-packages\django\core\handlers\base.py", line 187, in _get_response
    response = self.process_exception_by_middleware(e, request)
  File "E:\BrandMax\lib\site-packages\django\core\handlers\base.py", line 185, in _get_response
    response = wrapped_callback(request, *callback_args, **callback_kwargs)
  File "E:\BrandMax\lib\site-packages\django\views\generic\base.py", line 68, in view
    return self.dispatch(request, *args, **kwargs)
  File "E:\BrandMax\lib\site-packages\django\views\generic\base.py", line 88, in dispatch
    return handler(request, *args, **kwargs)
  File "E:\BrandMax\ExcelImport\excel_import\views.py", line 307, in get
    return render(request,'base.html')
  File "E:\BrandMax\lib\site-packages\django\shortcuts.py", line 30, in render
    content = loader.render_to_string(template_name, context, request, using=using)
  File "E:\BrandMax\lib\site-packages\django\template\loader.py", line 68, in render_to_string
    return template.render(context, request)
  File "E:\BrandMax\lib\site-packages\django\template\backends\django.py", line 68, in render
    reraise(exc, self.backend)
  File "E:\BrandMax\lib\site-packages\django\template\backends\django.py", line 89, in reraise
    six.reraise(exc.__class__, new, sys.exc_info()[2])
  File "E:\BrandMax\lib\site-packages\django\utils\six.py", line 685, in reraise
    raise value.with_traceback(tb)
  File "E:\BrandMax\lib\site-packages\django\template\backends\django.py", line 66, in render
    return self.template.render(context)
  File "E:\BrandMax\lib\site-packages\django\template\base.py", line 207, in render
    return self._render(context)
  File "E:\BrandMax\lib\site-packages\django\template\base.py", line 199, in _render
    return self.nodelist.render(context)
  File "E:\BrandMax\lib\site-packages\django\template\base.py", line 990, in render
    bit = node.render_annotated(context)
  File "E:\BrandMax\lib\site-packages\django\template\base.py", line 957, in render_annotated
    return self.render(context)
  File "E:\BrandMax\lib\site-packages\django\template\loader_tags.py", line 216, in render
    return template.render(context)
  File "E:\BrandMax\lib\site-packages\django\template\base.py", line 209, in render
    return self._render(context)
  File "E:\BrandMax\lib\site-packages\django\template\base.py", line 199, in _render
    return self.nodelist.render(context)
  File "E:\BrandMax\lib\site-packages\django\template\base.py", line 990, in render
    bit = node.render_annotated(context)
  File "E:\BrandMax\lib\site-packages\django\template\base.py", line 957, in render_annotated
    return self.render(context)
  File "E:\BrandMax\lib\site-packages\django\template\loader_tags.py", line 154, in render
    compiled_parent = self.get_parent(context)
  File "E:\BrandMax\lib\site-packages\django\template\loader_tags.py", line 151, in get_parent
    return self.find_template(parent, context)
  File "E:\BrandMax\lib\site-packages\django\template\loader_tags.py", line 131, in find_template
    template_name, skip=history,
  File "E:\BrandMax\lib\site-packages\django\template\engine.py", line 148, in find_template
    raise TemplateDoesNotExist(name, tried=tried)
django.template.exceptions.TemplateDoesNotExist: base.html
 2019-04-18 17:59:28 exception.py[line:135] ERROR Internal Server Error: /index
Traceback (most recent call last):
  File "E:\BrandMax\lib\site-packages\django\template\backends\django.py", line 66, in render
    return self.template.render(context)
  File "E:\BrandMax\lib\site-packages\django\template\base.py", line 207, in render
    return self._render(context)
  File "E:\BrandMax\lib\site-packages\django\template\base.py", line 199, in _render
    return self.nodelist.render(context)
  File "E:\BrandMax\lib\site-packages\django\template\base.py", line 990, in render
    bit = node.render_annotated(context)
  File "E:\BrandMax\lib\site-packages\django\template\base.py", line 957, in render_annotated
    return self.render(context)
  File "E:\BrandMax\lib\site-packages\django\template\loader_tags.py", line 216, in render
    return template.render(context)
  File "E:\BrandMax\lib\site-packages\django\template\base.py", line 209, in render
    return self._render(context)
  File "E:\BrandMax\lib\site-packages\django\template\base.py", line 199, in _render
    return self.nodelist.render(context)
  File "E:\BrandMax\lib\site-packages\django\template\base.py", line 990, in render
    bit = node.render_annotated(context)
  File "E:\BrandMax\lib\site-packages\django\template\base.py", line 957, in render_annotated
    return self.render(context)
  File "E:\BrandMax\lib\site-packages\django\template\loader_tags.py", line 154, in render
    compiled_parent = self.get_parent(context)
  File "E:\BrandMax\lib\site-packages\django\template\loader_tags.py", line 151, in get_parent
    return self.find_template(parent, context)
  File "E:\BrandMax\lib\site-packages\django\template\loader_tags.py", line 131, in find_template
    template_name, skip=history,
  File "E:\BrandMax\lib\site-packages\django\template\engine.py", line 148, in find_template
    raise TemplateDoesNotExist(name, tried=tried)
django.template.exceptions.TemplateDoesNotExist: base.html

During handling of the above exception, another exception occurred:

Traceback (most recent call last):
  File "E:\BrandMax\lib\site-packages\django\core\handlers\exception.py", line 41, in inner
    response = get_response(request)
  File "E:\BrandMax\lib\site-packages\django\core\handlers\base.py", line 187, in _get_response
    response = self.process_exception_by_middleware(e, request)
  File "E:\BrandMax\lib\site-packages\django\core\handlers\base.py", line 185, in _get_response
    response = wrapped_callback(request, *callback_args, **callback_kwargs)
  File "E:\BrandMax\lib\site-packages\django\views\generic\base.py", line 68, in view
    return self.dispatch(request, *args, **kwargs)
  File "E:\BrandMax\lib\site-packages\django\views\generic\base.py", line 88, in dispatch
    return handler(request, *args, **kwargs)
  File "E:\BrandMax\ExcelImport\excel_import\views.py", line 307, in get
    return render(request,'base.html')
  File "E:\BrandMax\lib\site-packages\django\shortcuts.py", line 30, in render
    content = loader.render_to_string(template_name, context, request, using=using)
  File "E:\BrandMax\lib\site-packages\django\template\loader.py", line 68, in render_to_string
    return template.render(context, request)
  File "E:\BrandMax\lib\site-packages\django\template\backends\django.py", line 68, in render
    reraise(exc, self.backend)
  File "E:\BrandMax\lib\site-packages\django\template\backends\django.py", line 89, in reraise
    six.reraise(exc.__class__, new, sys.exc_info()[2])
  File "E:\BrandMax\lib\site-packages\django\utils\six.py", line 685, in reraise
    raise value.with_traceback(tb)
  File "E:\BrandMax\lib\site-packages\django\template\backends\django.py", line 66, in render
    return self.template.render(context)
  File "E:\BrandMax\lib\site-packages\django\template\base.py", line 207, in render
    return self._render(context)
  File "E:\BrandMax\lib\site-packages\django\template\base.py", line 199, in _render
    return self.nodelist.render(context)
  File "E:\BrandMax\lib\site-packages\django\template\base.py", line 990, in render
    bit = node.render_annotated(context)
  File "E:\BrandMax\lib\site-packages\django\template\base.py", line 957, in render_annotated
    return self.render(context)
  File "E:\BrandMax\lib\site-packages\django\template\loader_tags.py", line 216, in render
    return template.render(context)
  File "E:\BrandMax\lib\site-packages\django\template\base.py", line 209, in render
    return self._render(context)
  File "E:\BrandMax\lib\site-packages\django\template\base.py", line 199, in _render
    return self.nodelist.render(context)
  File "E:\BrandMax\lib\site-packages\django\template\base.py", line 990, in render
    bit = node.render_annotated(context)
  File "E:\BrandMax\lib\site-packages\django\template\base.py", line 957, in render_annotated
    return self.render(context)
  File "E:\BrandMax\lib\site-packages\django\template\loader_tags.py", line 154, in render
    compiled_parent = self.get_parent(context)
  File "E:\BrandMax\lib\site-packages\django\template\loader_tags.py", line 151, in get_parent
    return self.find_template(parent, context)
  File "E:\BrandMax\lib\site-packages\django\template\loader_tags.py", line 131, in find_template
    template_name, skip=history,
  File "E:\BrandMax\lib\site-packages\django\template\engine.py", line 148, in find_template
    raise TemplateDoesNotExist(name, tried=tried)
django.template.exceptions.TemplateDoesNotExist: base.html
 2019-04-18 18:14:37 exception.py[line:135] ERROR Internal Server Error: /index
Traceback (most recent call last):
  File "E:\BrandMax\lib\site-packages\django\core\handlers\exception.py", line 41, in inner
    response = get_response(request)
  File "E:\BrandMax\lib\site-packages\django\core\handlers\base.py", line 187, in _get_response
    response = self.process_exception_by_middleware(e, request)
  File "E:\BrandMax\lib\site-packages\django\core\handlers\base.py", line 185, in _get_response
    response = wrapped_callback(request, *callback_args, **callback_kwargs)
  File "E:\BrandMax\lib\site-packages\django\views\generic\base.py", line 68, in view
    return self.dispatch(request, *args, **kwargs)
  File "E:\BrandMax\lib\site-packages\django\views\generic\base.py", line 88, in dispatch
    return handler(request, *args, **kwargs)
  File "E:\BrandMax\ExcelImport\excel_import\views.py", line 307, in get
    return render(request,'export_excel2.html.html')
  File "E:\BrandMax\lib\site-packages\django\shortcuts.py", line 30, in render
    content = loader.render_to_string(template_name, context, request, using=using)
  File "E:\BrandMax\lib\site-packages\django\template\loader.py", line 67, in render_to_string
    template = get_template(template_name, using=using)
  File "E:\BrandMax\lib\site-packages\django\template\loader.py", line 25, in get_template
    raise TemplateDoesNotExist(template_name, chain=chain)
django.template.exceptions.TemplateDoesNotExist: export_excel2.html.html
 2019-04-18 18:14:39 exception.py[line:135] ERROR Internal Server Error: /index
Traceback (most recent call last):
  File "E:\BrandMax\lib\site-packages\django\core\handlers\exception.py", line 41, in inner
    response = get_response(request)
  File "E:\BrandMax\lib\site-packages\django\core\handlers\base.py", line 187, in _get_response
    response = self.process_exception_by_middleware(e, request)
  File "E:\BrandMax\lib\site-packages\django\core\handlers\base.py", line 185, in _get_response
    response = wrapped_callback(request, *callback_args, **callback_kwargs)
  File "E:\BrandMax\lib\site-packages\django\views\generic\base.py", line 68, in view
    return self.dispatch(request, *args, **kwargs)
  File "E:\BrandMax\lib\site-packages\django\views\generic\base.py", line 88, in dispatch
    return handler(request, *args, **kwargs)
  File "E:\BrandMax\ExcelImport\excel_import\views.py", line 307, in get
    return render(request,'export_excel2.html.html')
  File "E:\BrandMax\lib\site-packages\django\shortcuts.py", line 30, in render
    content = loader.render_to_string(template_name, context, request, using=using)
  File "E:\BrandMax\lib\site-packages\django\template\loader.py", line 67, in render_to_string
    template = get_template(template_name, using=using)
  File "E:\BrandMax\lib\site-packages\django\template\loader.py", line 25, in get_template
    raise TemplateDoesNotExist(template_name, chain=chain)
django.template.exceptions.TemplateDoesNotExist: export_excel2.html.html
 2019-04-18 18:36:01 views.py[line:248] ERROR 'str' object cannot be interpreted as an integer
 2019-04-18 18:36:01 views.py[line:248] ERROR 'str' object cannot be interpreted as an integer
 2019-04-18 18:36:01 views.py[line:248] ERROR 'str' object cannot be interpreted as an integer
 2019-04-18 18:36:01 views.py[line:248] ERROR '趋势图数据'
 2019-04-18 18:36:01 views.py[line:248] ERROR '计划'
 2019-04-18 18:36:01 views.py[line:248] ERROR 'str' object cannot be interpreted as an integer
 2019-04-18 18:56:10 views.py[line:246] ERROR 'str' object cannot be interpreted as an integer
 2019-04-18 18:56:10 views.py[line:246] ERROR 'str' object cannot be interpreted as an integer
 2019-04-18 18:56:10 views.py[line:246] ERROR '趋势图数据'
 2019-04-18 18:56:10 views.py[line:246] ERROR '计划'
 2019-04-18 18:56:10 views.py[line:246] ERROR 'str' object cannot be interpreted as an integer
 2019-04-18 18:56:10 views.py[line:246] ERROR Invalid field name(s) for model BxEverydayData: 'end_time', 'pic_count', 'pic_time_gap', 'start_time', 'station_name', 'status'.
 2019-04-18 18:56:10 views.py[line:246] ERROR 'str' object cannot be interpreted as an integer
 2019-04-19 10:16:02 views.py[line:248] ERROR '趋势图数据'
 2019-04-19 10:16:02 views.py[line:248] ERROR 'str' object cannot be interpreted as an integer
 2019-04-19 10:16:02 views.py[line:248] ERROR 'str' object cannot be interpreted as an integer
 2019-04-19 10:16:02 views.py[line:248] ERROR '计划'
 2019-04-19 10:16:02 views.py[line:248] ERROR Invalid field name(s) for model BxEverydayContrastData: 'end_time', 'pic_count', 'pic_time_gap', 'start_time', 'station_id', 'station_name', 'status'.
 2019-04-19 10:16:02 views.py[line:248] ERROR 'str' object cannot be interpreted as an integer
 2019-04-19 10:16:03 views.py[line:248] ERROR 'str' object cannot be interpreted as an integer
 2019-04-19 10:19:09 views.py[line:248] ERROR '趋势图数据'
 2019-04-19 10:19:09 views.py[line:248] ERROR 'str' object cannot be interpreted as an integer
 2019-04-19 10:19:09 views.py[line:248] ERROR 'str' object cannot be interpreted as an integer
 2019-04-19 10:19:09 views.py[line:248] ERROR 'str' object cannot be interpreted as an integer
 2019-04-19 10:19:09 views.py[line:248] ERROR '计划'
 2019-04-19 10:19:10 views.py[line:248] ERROR 'str' object cannot be interpreted as an integer
 2019-04-19 10:27:36 views.py[line:247] ERROR '趋势图数据'
 2019-04-19 10:27:36 views.py[line:247] ERROR 'str' object cannot be interpreted as an integer
 2019-04-19 10:27:36 views.py[line:247] ERROR 'str' object cannot be interpreted as an integer
 2019-04-19 10:27:36 views.py[line:247] ERROR 'str' object cannot be interpreted as an integer
 2019-04-19 10:27:36 views.py[line:247] ERROR '计划'
 2019-04-19 10:27:36 views.py[line:247] ERROR Invalid field name(s) for model BxDevice: 'end_time', 'pic_count', 'pic_time_gap', 'start_time', 'station_name', 'status'.
 2019-04-19 10:27:36 views.py[line:247] ERROR 'str' object cannot be interpreted as an integer
 2019-04-19 10:50:14 views.py[line:247] ERROR '趋势图数据'
 2019-04-19 10:50:14 views.py[line:247] ERROR 'str' object cannot be interpreted as an integer
 2019-04-19 10:50:14 views.py[line:247] ERROR 'str' object cannot be interpreted as an integer
 2019-04-19 10:50:14 views.py[line:247] ERROR 'str' object cannot be interpreted as an integer
 2019-04-19 10:50:14 views.py[line:247] ERROR '计划'
 2019-04-19 10:50:14 views.py[line:247] ERROR 'str' object cannot be interpreted as an integer
 2019-04-19 10:53:31 views.py[line:247] ERROR 'str' object cannot be interpreted as an integer
 2019-04-19 10:53:31 views.py[line:247] ERROR '趋势图数据'
 2019-04-19 10:53:31 views.py[line:247] ERROR 'str' object cannot be interpreted as an integer
 2019-04-19 10:53:31 views.py[line:247] ERROR 'str' object cannot be interpreted as an integer
 2019-04-19 10:53:31 views.py[line:247] ERROR '计划'
 2019-04-19 10:53:31 views.py[line:247] ERROR 'str' object cannot be interpreted as an integer
 2019-04-19 10:57:20 views.py[line:247] ERROR 'str' object cannot be interpreted as an integer
 2019-04-19 10:57:21 views.py[line:247] ERROR 'str' object cannot be interpreted as an integer
 2019-04-19 10:57:21 views.py[line:247] ERROR 'str' object cannot be interpreted as an integer
 2019-04-19 10:57:21 views.py[line:247] ERROR 'str' object cannot be interpreted as an integer
 2019-04-19 10:57:21 views.py[line:247] ERROR 'str' object cannot be interpreted as an integer
 2019-04-19 10:57:21 views.py[line:247] ERROR 'str' object cannot be interpreted as an integer
 2019-04-19 10:57:21 views.py[line:247] ERROR 'str' object cannot be interpreted as an integer
 2019-04-19 11:12:20 views.py[line:215] ERROR '趋势图数据'
 2019-04-19 11:12:20 views.py[line:215] ERROR 'str' object cannot be interpreted as an integer
 2019-04-19 11:12:20 views.py[line:215] ERROR '计划'
 2019-04-19 11:12:20 views.py[line:215] ERROR Invalid field name(s) for model BxEverydayData: 'end_time', 'pic_count', 'pic_time_gap', 'start_time', 'station_name', 'status'.
 2019-04-19 11:12:20 views.py[line:215] ERROR 'str' object cannot be interpreted as an integer
 2019-04-19 11:12:20 views.py[line:215] ERROR 'str' object cannot be interpreted as an integer
 2019-04-19 11:12:20 views.py[line:215] ERROR 'str' object cannot be interpreted as an integer
